<?xml version="1.0"?>
<robot xmlns:xacro="http://ros.org/wiki/xacro">  
  <xacro:macro name="agv_wheel" params="xyz_hub rpy_hub side">    

  <link name='hub_${side}_link'>
	  <collision>
		  <origin xyz="0 0 0" rpy="0 0 1.570796"/>
		  <geometry>
			<mesh filename="package://agv_description/meshes/Stl-22-06-2018/teker_ic.stl" scale="0.001 0.001 0.001"/>			  			  
		  </geometry>
	  </collision>
    <visual>
      <origin xyz="0 0 0" rpy=" 0 0 1.570796"/>
      <geometry>
	    <mesh filename="package://agv_description/meshes/Stl-22-06-2018/teker_ic.stl" scale="0.001 0.001 0.001"/>
      </geometry>
    </visual>	  
    <xacro:cylinder_inertial radius="0.15" length="0.02" mass="0.1"/>
  </link>
  <joint name="hub_${side}_base" type="continuous">
    <origin xyz="${xyz_hub}" rpy="${rpy_hub}"/>
    <parent link="base_link"/>
    <child link="hub_${side}_link"/>
    <axis xyz="0 1 0"/>    
  </joint> 
  <link name='wheel_${side}_link'>
	<collision>
	  <origin xyz="0 0 0" rpy="0 0 1.570796"/>
	  <geometry>
		  <!--<box size="0.8 0.05 0.06"/>-->
		<mesh filename="package://agv_description/meshes/Stl-22-06-2018/teker_dis.stl" scale="0.001 0.001 0.001"/>			  			  
	  </geometry>
	</collision>
    <visual>
      <origin xyz="0 0 0" rpy=" 0 0 1.570796"/>
      <geometry>
	    <mesh filename="package://agv_description/meshes/Stl-22-06-2018/teker_dis.stl" scale="0.001 0.001 0.001"/>
      </geometry>
    </visual>	  
  </link>  
  <gazebo reference="wheel_${side}_link">
    <material value="Gazebo/Green"/>
  </gazebo>     
  <joint name="hub_${side}_wheel" type="fixed">
    <origin xyz="0 0 0" rpy="0 0 0"/>
    <parent link="hub_${side}_link"/>
    <child link="wheel_${side}_link"/>
    <axis xyz="0 1 0"/>    
  </joint>
  
  </xacro:macro>
 </robot>
